data: <?xml version="1.0" ?> <!-- =================================================================================== --> <!-- |    This document was autogenerated by xacro from /home/alexander/simplebot2/ros2_workspace/install/simplebot_description/share/simplebot_description/src/description/simplebot_description.urdf | --> <!-- |    EDITING THIS FILE BY HAND IS NOT RECOMMENDED                                 | --> <!-- =================================================================================== --> <robot name="onshape"> <link name="base_link"/> <joint name="base_link_to_base" type="fixed"> <parent link="base_link"/> <child link="frame2"/> <origin rpy="0.0 0 0" xyz="0 0 0"/> </joint> <link name="frame2"> <visual> <origin rpy="0 -0 0" xyz="0.013397693634033203125 -0.019190251529216773019 0.016505338315628892421"/> <geometry> <mesh filename="file:///home/alexander/simplebot2/ros2_workspace/install/simplebot_description/share/simplebot_description/meshes/frame2.stl"/> </geometry> <material name="frame2_material"> <color rgba="0.61568627450980395466 0.81176470588235294379 0.92941176470588238168 1.0"/> </material> </visual> <collision> <origin rpy="0 -0 0" xyz="0.013397693634033203125 -0.019190251529216773019 0.016505338315628892421"/> <geometry> <mesh filename="file:///home/alexander/simplebot2/ros2_workspace/install/simplebot_description/share/simplebot_description/meshes/frame2.stl"/> </geometry> </collision> <inertial> <origin rpy="0 0 0" xyz="0.01339769362719597616 0.035598667914564202652 0.065722307056853807028"/> <mass value="0.83471239669910590742"/> <inertia ixx="0.0033281987957472980097" ixy="-1.3809149186762488429e-10" ixz="-2.9054647173974031066e-12" iyy="0.0021781731379015558878" iyz="0.00043078360211500158752" izz="0.0043042325095105533894"/> </inertial> </link> <link name="front_left"> <visual> <origin rpy="-1.570796326794896558 -0 0" xyz="-0.048588856906500499377 0.0025195016467438879904 0.0097454869585663073117"/> <geometry> <mesh filename="file:///home/alexander/simplebot2/ros2_workspace/install/simplebot_description/share/simplebot_description/meshes/front_left.stl"/> </geometry> <material name="front_left_material"> <color rgba="0.81568627450980391025 0.84705882352941175295 0.68235294117647060652 1.0"/> </material> </visual> <collision> <origin rpy="-1.570796326794896558 -0 0" xyz="-0.048588856906500499377 0.0025195016467438879904 0.0097454869585663073117"/> <geometry> <mesh filename="file:///home/alexander/simplebot2/ros2_workspace/install/simplebot_description/share/simplebot_description/meshes/front_left.stl"/> </geometry> </collision> <inertial> <origin rpy="0 0 0" xyz="0 2.0816681711721685133e-16 -0.015531989140698539142"/> <mass value="0.053246309071214095732"/> <inertia ixx="1.3015782152348844185e-05" ixy="0" ixz="0" iyy="1.3015782152347993764e-05" iyz="0" izz="1.93168814079787818e-05"/> </inertial> </link> <joint name="front_left_wheel" type="continuous"> <origin rpy="-3.141592653589793116 -1.570796326794896558 0" xyz="-0.082110586913439115309 0.13080974847078327694 0.034005338315628894086"/> <parent link="frame2"/> <child link="front_left"/> <axis xyz="0 0 1"/> <limit effort="1" velocity="20"/> <joint_properties friction="0.0"/> </joint> <link name="front_right"> <visual> <origin rpy="1.570796326794896558 -0 0" xyz="-0.092487330523870203702 0.030194420845917696594 -0.059454826762777898685"/> <geometry> <mesh filename="file:///home/alexander/simplebot2/ros2_workspace/install/simplebot_description/share/simplebot_description/meshes/front_right.stl"/> </geometry> <material name="front_right_material"> <color rgba="0.61568627450980395466 0.5803921568627451455 0.56470588235294116863 1.0"/> </material> </visual> <collision> <origin rpy="1.570796326794896558 -0 0" xyz="-0.092487330523870203702 0.030194420845917696594 -0.059454826762777898685"/> <geometry> <mesh filename="file:///home/alexander/simplebot2/ros2_workspace/install/simplebot_description/share/simplebot_description/meshes/front_right.stl"/> </geometry> </collision> <inertial> <origin rpy="0 0 0" xyz="-2.3592239273284576484e-16 1.8041124150158793782e-16 -0.015580103226351262047"/> <mass value="0.053246309071214012465"/> <inertia ixx="1.3016775931929221903e-05" ixy="0" ixz="0" iyy="1.3016775931929974069e-05" iyz="0" izz="1.931688140797337773e-05"/> </inertial> </link> <joint name="front_right_wheel" type="continuous"> <origin rpy="-3.141592653589793116 1.570796326794896558 0" xyz="0.10890597418150550768 0.13080974847078327694 0.034005338315628907964"/> <parent link="frame2"/> <child link="front_right"/> <axis xyz="0 0 1"/> <limit effort="1" velocity="20"/> <joint_properties friction="0.0"/> </joint> <link name="rear_left"> <visual> <origin rpy="1.570796326794896558 -0 0" xyz="-0.092487330523870203702 0.030194420845917700064 -0.059454826762777898685"/> <geometry> <mesh filename="file:///home/alexander/simplebot2/ros2_workspace/install/simplebot_description/share/simplebot_description/meshes/rear_left.stl"/> </geometry> <material name="rear_left_material"> <color rgba="0.61568627450980395466 0.5803921568627451455 0.56470588235294116863 1.0"/> </material> </visual> <collision> <origin rpy="1.570796326794896558 -0 0" xyz="-0.092487330523870203702 0.030194420845917700064 -0.059454826762777898685"/> <geometry> <mesh filename="file:///home/alexander/simplebot2/ros2_workspace/install/simplebot_description/share/simplebot_description/meshes/rear_left.stl"/> </geometry> </collision> <inertial> <origin rpy="0 0 0" xyz="-2.3592239273284576484e-16 1.8388068845354155201e-16 -0.015580103226351262047"/> <mass value="0.053246309071214012465"/> <inertia ixx="1.3016775931929213433e-05" ixy="0" ixz="0" iyy="1.3016775931929972375e-05" iyz="0" izz="1.9316881407973370954e-05"/> </inertial> </link> <joint name="rear_right_wheel" type="continuous"> <origin rpy="-3.141592653589793116 -1.570796326794896558 0" xyz="-0.082110586913439101431 0.00080974847078321698923 0.034005338315628894086"/> <parent link="frame2"/> <child link="rear_left"/> <axis xyz="0 0 1"/> <limit effort="1" velocity="20"/> <joint_properties friction="0.0"/> </joint> <link name="rear_right"> <visual> <origin rpy="-1.570796326794896558 -0 0" xyz="-0.048588856906500499377 0.0025195016467438992661 0.0097454869585663073117"/> <geometry> <mesh filename="file:///home/alexander/simplebot2/ros2_workspace/install/simplebot_description/share/simplebot_description/meshes/rear_right.stl"/> </geometry> <material name="rear_right_material"> <color rgba="0.81568627450980391025 0.84705882352941175295 0.68235294117647060652 1.0"/> </material> </visual> <collision> <origin rpy="-1.570796326794896558 -0 0" xyz="-0.048588856906500499377 0.0025195016467438992661 0.0097454869585663073117"/> <geometry> <mesh filename="file:///home/alexander/simplebot2/ros2_workspace/install/simplebot_description/share/simplebot_description/meshes/rear_right.stl"/> </geometry> </collision> <inertial> <origin rpy="0 0 0" xyz="0 2.1987620058006029922e-16 -0.015531989140698539142"/> <mass value="0.053246309071214095732"/> <inertia ixx="1.3015782152348844185e-05" ixy="0" ixz="0" iyy="1.3015782152347993764e-05" iyz="0" izz="1.9316881407978785188e-05"/> </inertial> </link> <joint name="rear_left_wheel" type="continuous"> <origin rpy="-3.141592653589793116 1.570796326794896558 0" xyz="0.10890597418150552156 0.00080974847078321698923 0.034005338315628894086"/> <parent link="frame2"/> <child link="rear_right"/> <axis xyz="0 0 1"/> <limit effort="1" velocity="20"/> <joint_properties friction="0.0"/> </joint> </robot>
---
data: <?xml version="1.0" ?> <!-- =================================================================================== --> <!-- |    This document was autogenerated by xacro from /home/alexander/simplebot2/ros2_workspace/install/simplebot_description/share/simplebot_description/src/description/simplebot_description.urdf | --> <!-- |    EDITING THIS FILE BY HAND IS NOT RECOMMENDED                                 | --> <!-- =================================================================================== --> <!-- Generated using onshape-to-robot --> <!-- Onshape https://cad.onshape.com/documents/58d69eaf54d5097cb2ee2932/w/94ca09f7b1264f3339bd84c4/e/3159eab8c0fb4f293d9f6567 --> <robot name="simplebot2"> <!-- Link base_link --> <link name="base_link"> <inertial> <origin rpy="0 0 0" xyz="0.0400408 0.188869 -0.0707852"/> <mass value="0.426296"/> <inertia ixx="0.00190478" ixy="-9.36048e-11" ixz="-2.8119e-08" iyy="0.00184221" iyz="-1.22606e-12" izz="0.00332037"/> </inertial> <!-- Part frame3 --> <visual> <origin rpy="0 -0 0" xyz="0.0400408 0.103869 -0.0968943"/> <geometry> <mesh filename="file:///home/alexander/simplebot2/ros2_workspace/install/simplebot_description/share/simplebot_description/meshes/frame3.stl"/> </geometry> <material name="frame3_material"> <color rgba="0.615686 0.811765 0.929412 1"/> </material> </visual> <collision> <origin rpy="0 -0 0" xyz="0.0400408 0.103869 -0.0968943"/> <geometry> <mesh filename="file:///home/alexander/simplebot2/ros2_workspace/install/simplebot_description/share/simplebot_description/meshes/frame3.stl"/> </geometry> </collision> <!-- Part side_bracket_right --> <visual> <origin rpy="0 -0 0" xyz="0.0400408 0.103869 -0.0968943"/> <geometry> <mesh filename="file:///home/alexander/simplebot2/ros2_workspace/install/simplebot_description/share/simplebot_description/meshes/side_bracket_right.stl"/> </geometry> <material name="side_bracket_right_material"> <color rgba="0.647059 0.647059 0.647059 1"/> </material> </visual> <collision> <origin rpy="0 -0 0" xyz="0.0400408 0.103869 -0.0968943"/> <geometry> <mesh filename="file:///home/alexander/simplebot2/ros2_workspace/install/simplebot_description/share/simplebot_description/meshes/side_bracket_right.stl"/> </geometry> </collision> <!-- Part frame2 --> <visual> <origin rpy="0 -0 0" xyz="0.0400408 0.103869 -0.0968943"/> <geometry> <mesh filename="file:///home/alexander/simplebot2/ros2_workspace/install/simplebot_description/share/simplebot_description/meshes/frame2.stl"/> </geometry> <material name="frame2_material"> <color rgba="0.615686 0.811765 0.929412 1"/> </material> </visual> <collision> <origin rpy="0 -0 0" xyz="0.0400408 0.103869 -0.0968943"/> <geometry> <mesh filename="file:///home/alexander/simplebot2/ros2_workspace/install/simplebot_description/share/simplebot_description/meshes/frame2.stl"/> </geometry> </collision> <!-- Part part_33 --> <visual> <origin rpy="0 -0 0" xyz="0.0400408 0.103869 -0.0968943"/> <geometry> <mesh filename="file:///home/alexander/simplebot2/ros2_workspace/install/simplebot_description/share/simplebot_description/meshes/part_33.stl"/> </geometry> <material name="part_33_material"> <color rgba="0.980392 0.713725 0.00392157 1"/> </material> </visual> <collision> <origin rpy="0 -0 0" xyz="0.0400408 0.103869 -0.0968943"/> <geometry> <mesh filename="file:///home/alexander/simplebot2/ros2_workspace/install/simplebot_description/share/simplebot_description/meshes/part_33.stl"/> </geometry> </collision> <!-- Part motor_bracket_front_right --> <visual> <origin rpy="0 -0 0" xyz="0.0400408 0.103869 -0.0968943"/> <geometry> <mesh filename="file:///home/alexander/simplebot2/ros2_workspace/install/simplebot_description/share/simplebot_description/meshes/motor_bracket_front_right.stl"/> </geometry> <material name="motor_bracket_front_right_material"> <color rgba="0.647059 0.647059 0.647059 1"/> </material> </visual> <collision> <origin rpy="0 -0 0" xyz="0.0400408 0.103869 -0.0968943"/> <geometry> <mesh filename="file:///home/alexander/simplebot2/ros2_workspace/install/simplebot_description/share/simplebot_description/meshes/motor_bracket_front_right.stl"/> </geometry> </collision> <!-- Part part_1 --> <visual> <origin rpy="0 -0 0" xyz="0.0400408 0.143869 -0.0968943"/> <geometry> <mesh filename="file:///home/alexander/simplebot2/ros2_workspace/install/simplebot_description/share/simplebot_description/meshes/part_1.stl"/> </geometry> <material name="part_1_material"> <color rgba="0.647059 0.647059 0.647059 1"/> </material> </visual> <collision> <origin rpy="0 -0 0" xyz="0.0400408 0.143869 -0.0968943"/> <geometry> <mesh filename="file:///home/alexander/simplebot2/ros2_workspace/install/simplebot_description/share/simplebot_description/meshes/part_1.stl"/> </geometry> </collision> <!-- Part motor_bracket_front_left --> <visual> <origin rpy="0 -0 0" xyz="0.0400408 0.103869 -0.0968943"/> <geometry> <mesh filename="file:///home/alexander/simplebot2/ros2_workspace/install/simplebot_description/share/simplebot_description/meshes/motor_bracket_front_left.stl"/> </geometry> <material name="motor_bracket_front_left_material"> <color rgba="0.647059 0.647059 0.647059 1"/> </material> </visual> <collision> <origin rpy="0 -0 0" xyz="0.0400408 0.103869 -0.0968943"/> <geometry> <mesh filename="file:///home/alexander/simplebot2/ros2_workspace/install/simplebot_description/share/simplebot_description/meshes/motor_bracket_front_left.stl"/> </geometry> </collision> <!-- Part frame4 --> <visual> <origin rpy="0 -0 0" xyz="0.0400408 0.103869 -0.0968943"/> <geometry> <mesh filename="file:///home/alexander/simplebot2/ros2_workspace/install/simplebot_description/share/simplebot_description/meshes/frame4.stl"/> </geometry> <material name="frame4_material"> <color rgba="0.615686 0.811765 0.929412 1"/> </material> </visual> <collision> <origin rpy="0 -0 0" xyz="0.0400408 0.103869 -0.0968943"/> <geometry> <mesh filename="file:///home/alexander/simplebot2/ros2_workspace/install/simplebot_description/share/simplebot_description/meshes/frame4.stl"/> </geometry> </collision> <!-- Part motor_bracket_rear_left --> <visual> <origin rpy="0 -0 0" xyz="0.0400408 0.103869 -0.0968943"/> <geometry> <mesh filename="file:///home/alexander/simplebot2/ros2_workspace/install/simplebot_description/share/simplebot_description/meshes/motor_bracket_rear_left.stl"/> </geometry> <material name="motor_bracket_rear_left_material"> <color rgba="0.647059 0.647059 0.647059 1"/> </material> </visual> <collision> <origin rpy="0 -0 0" xyz="0.0400408 0.103869 -0.0968943"/> <geometry> <mesh filename="file:///home/alexander/simplebot2/ros2_workspace/install/simplebot_description/share/simplebot_description/meshes/motor_bracket_rear_left.stl"/> </geometry> </collision> <!-- Part part_1_2 --> <visual> <origin rpy="-6.16298e-33 -0 0" xyz="0.0400408 0.103869 -0.0968943"/> <geometry> <mesh filename="file:///home/alexander/simplebot2/ros2_workspace/install/simplebot_description/share/simplebot_description/meshes/part_1__2.stl"/> </geometry> <material name="part_1_2_material"> <color rgba="0.231373 0.380392 0.705882 1"/> </material> </visual> <collision> <origin rpy="-6.16298e-33 -0 0" xyz="0.0400408 0.103869 -0.0968943"/> <geometry> <mesh filename="file:///home/alexander/simplebot2/ros2_workspace/install/simplebot_description/share/simplebot_description/meshes/part_1__2.stl"/> </geometry> </collision> <!-- Part part_22 --> <visual> <origin rpy="0 -0 0" xyz="0.0400408 0.143869 -0.0968943"/> <geometry> <mesh filename="file:///home/alexander/simplebot2/ros2_workspace/install/simplebot_description/share/simplebot_description/meshes/part_22.stl"/> </geometry> <material name="part_22_material"> <color rgba="0.917647 0.917647 0.917647 1"/> </material> </visual> <collision> <origin rpy="0 -0 0" xyz="0.0400408 0.143869 -0.0968943"/> <geometry> <mesh filename="file:///home/alexander/simplebot2/ros2_workspace/install/simplebot_description/share/simplebot_description/meshes/part_22.stl"/> </geometry> </collision> <!-- Part motor_bracket_rear_right --> <visual> <origin rpy="0 -0 0" xyz="0.0400408 0.103869 -0.0968943"/> <geometry> <mesh filename="file:///home/alexander/simplebot2/ros2_workspace/install/simplebot_description/share/simplebot_description/meshes/motor_bracket_rear_right.stl"/> </geometry> <material name="motor_bracket_rear_right_material"> <color rgba="0.647059 0.647059 0.647059 1"/> </material> </visual> <collision> <origin rpy="0 -0 0" xyz="0.0400408 0.103869 -0.0968943"/> <geometry> <mesh filename="file:///home/alexander/simplebot2/ros2_workspace/install/simplebot_description/share/simplebot_description/meshes/motor_bracket_rear_right.stl"/> </geometry> </collision> <!-- Part frame1 --> <visual> <origin rpy="0 -0 0" xyz="0.0400408 0.103869 -0.0968943"/> <geometry> <mesh filename="file:///home/alexander/simplebot2/ros2_workspace/install/simplebot_description/share/simplebot_description/meshes/frame1.stl"/> </geometry> <material name="frame1_material"> <color rgba="0.615686 0.811765 0.929412 1"/> </material> </visual> <collision> <origin rpy="0 -0 0" xyz="0.0400408 0.103869 -0.0968943"/> <geometry> <mesh filename="file:///home/alexander/simplebot2/ros2_workspace/install/simplebot_description/share/simplebot_description/meshes/frame1.stl"/> </geometry> </collision> <!-- Part side_bracket_left --> <visual> <origin rpy="0 -0 0" xyz="0.0400408 0.103869 -0.0968943"/> <geometry> <mesh filename="file:///home/alexander/simplebot2/ros2_workspace/install/simplebot_description/share/simplebot_description/meshes/side_bracket_left.stl"/> </geometry> <material name="side_bracket_left_material"> <color rgba="0.647059 0.647059 0.647059 1"/> </material> </visual> <collision> <origin rpy="0 -0 0" xyz="0.0400408 0.103869 -0.0968943"/> <geometry> <mesh filename="file:///home/alexander/simplebot2/ros2_workspace/install/simplebot_description/share/simplebot_description/meshes/side_bracket_left.stl"/> </geometry> </collision> <!-- Part motor_front_right --> <visual> <origin rpy="-1.5708 -0 0" xyz="0.0400408 0.236369 0.0706057"/> <geometry> <mesh filename="file:///home/alexander/simplebot2/ros2_workspace/install/simplebot_description/share/simplebot_description/meshes/motor_front_right.stl"/> </geometry> <material name="motor_front_right_material"> <color rgba="0.8 0.807843 0.8 1"/> </material> </visual> <collision> <origin rpy="-1.5708 -0 0" xyz="0.0400408 0.236369 0.0706057"/> <geometry> <mesh filename="file:///home/alexander/simplebot2/ros2_workspace/install/simplebot_description/share/simplebot_description/meshes/motor_front_right.stl"/> </geometry> </collision> <!-- Part motor_rear_left --> <visual> <origin rpy="-1.5708 -0 0" xyz="0.0400408 0.106369 -0.0593943"/> <geometry> <mesh filename="file:///home/alexander/simplebot2/ros2_workspace/install/simplebot_description/share/simplebot_description/meshes/motor_rear_left.stl"/> </geometry> <material name="motor_rear_left_material"> <color rgba="0.8 0.807843 0.8 1"/> </material> </visual> <collision> <origin rpy="-1.5708 -0 0" xyz="0.0400408 0.106369 -0.0593943"/> <geometry> <mesh filename="file:///home/alexander/simplebot2/ros2_workspace/install/simplebot_description/share/simplebot_description/meshes/motor_rear_left.stl"/> </geometry> </collision> <!-- Part motor_rear_right --> <visual> <origin rpy="1.5708 -0 0" xyz="0.0400408 0.141369 -0.0993943"/> <geometry> <mesh filename="file:///home/alexander/simplebot2/ros2_workspace/install/simplebot_description/share/simplebot_description/meshes/motor_rear_right.stl"/> </geometry> <material name="motor_rear_right_material"> <color rgba="0.8 0.807843 0.8 1"/> </material> </visual> <collision> <origin rpy="1.5708 -0 0" xyz="0.0400408 0.141369 -0.0993943"/> <geometry> <mesh filename="file:///home/alexander/simplebot2/ros2_workspace/install/simplebot_description/share/simplebot_description/meshes/motor_rear_right.stl"/> </geometry> </collision> <!-- Part base_link --> <visual> <origin rpy="0 -0 0" xyz="0.0400408 0.103869 -0.0968943"/> <geometry> <mesh filename="file:///home/alexander/simplebot2/ros2_workspace/install/simplebot_description/share/simplebot_description/meshes/base_link.stl"/> </geometry> <material name="base_link_material"> <color rgba="0.917647 0.917647 0.917647 1"/> </material> </visual> <collision> <origin rpy="0 -0 0" xyz="0.0400408 0.103869 -0.0968943"/> <geometry> <mesh filename="file:///home/alexander/simplebot2/ros2_workspace/install/simplebot_description/share/simplebot_description/meshes/base_link.stl"/> </geometry> </collision> <!-- Part part_27 --> <visual> <origin rpy="0 -0 0" xyz="0.0400408 0.103869 -0.0993343"/> <geometry> <mesh filename="file:///home/alexander/simplebot2/ros2_workspace/install/simplebot_description/share/simplebot_description/meshes/part_27.stl"/> </geometry> <material name="part_27_material"> <color rgba="0.980392 0.713725 0.00392157 1"/> </material> </visual> <collision> <origin rpy="0 -0 0" xyz="0.0400408 0.103869 -0.0993343"/> <geometry> <mesh filename="file:///home/alexander/simplebot2/ros2_workspace/install/simplebot_description/share/simplebot_description/meshes/part_27.stl"/> </geometry> </collision> <!-- Part motor_front_left --> <visual> <origin rpy="1.5708 -0 0" xyz="0.0400408 0.271369 -0.229394"/> <geometry> <mesh filename="file:///home/alexander/simplebot2/ros2_workspace/install/simplebot_description/share/simplebot_description/meshes/motor_front_left.stl"/> </geometry> <material name="motor_front_left_material"> <color rgba="0.8 0.807843 0.8 1"/> </material> </visual> <collision> <origin rpy="1.5708 -0 0" xyz="0.0400408 0.271369 -0.229394"/> <geometry> <mesh filename="file:///home/alexander/simplebot2/ros2_workspace/install/simplebot_description/share/simplebot_description/meshes/motor_front_left.stl"/> </geometry> </collision> </link> <!-- Link part_1 --> <link name="part_1"> <inertial> <origin rpy="0 0 0" xyz="0 0 0"/> <mass value="1e-09"/> <inertia ixx="1e-09" ixy="0" ixz="0" iyy="1e-09" iyz="0" izz="1e-09"/> </inertial> <!-- Part part_1_3 --> <visual> <origin rpy="1.5708 1.5708 0" xyz="0 0 0.0075"/> <geometry> <mesh filename="file:///home/alexander/simplebot2/ros2_workspace/install/simplebot_description/share/simplebot_description/meshes/part_1__3.stl"/> </geometry> <material name="part_1_3_material"> <color rgba="0.615686 0.811765 0.929412 1"/> </material> </visual> <collision> <origin rpy="1.5708 1.5708 0" xyz="0 0 0.0075"/> <geometry> <mesh filename="file:///home/alexander/simplebot2/ros2_workspace/install/simplebot_description/share/simplebot_description/meshes/part_1__3.stl"/> </geometry> </collision> </link> <!-- Joint from base_link to part_1 --> <joint name="Revolute 1" type="continuous"> <origin rpy="-1.5708 -0 1.5708" xyz="0.143049 0.123869 -0.0793943"/> <parent link="base_link"/> <child link="part_1"/> <axis xyz="0 0 1"/> <limit effort="10" lower="-3.141592653589793" upper="3.141592653589793" velocity="10"/> </joint> <!-- Link part_1_2 --> <link name="part_1_2"> <inertial> <origin rpy="0 0 0" xyz="0 0 0"/> <mass value="1e-09"/> <inertia ixx="1e-09" ixy="0" ixz="0" iyy="1e-09" iyz="0" izz="1e-09"/> </inertial> <!-- Part part_1_4 --> <visual> <origin rpy="1.5708 1.5708 0" xyz="0 0 0.0075"/> <geometry> <mesh filename="file:///home/alexander/simplebot2/ros2_workspace/install/simplebot_description/share/simplebot_description/meshes/part_1__3.stl"/> </geometry> <material name="part_1_4_material"> <color rgba="0.615686 0.811765 0.929412 1"/> </material> </visual> <collision> <origin rpy="1.5708 1.5708 0" xyz="0 0 0.0075"/> <geometry> <mesh filename="file:///home/alexander/simplebot2/ros2_workspace/install/simplebot_description/share/simplebot_description/meshes/part_1__3.stl"/> </geometry> </collision> </link> <!-- Joint from base_link to part_1_2 --> <joint name="Revolute 2" type="continuous"> <origin rpy="-1.5708 -0 1.5708" xyz="0.143049 0.253869 -0.0793943"/> <parent link="base_link"/> <child link="part_1_2"/> <axis xyz="0 0 1"/> <limit effort="10" lower="-3.141592653589793" upper="3.141592653589793" velocity="10"/> </joint> <!-- Link part_1_3 --> <link name="part_1_3"> <inertial> <origin rpy="0 0 0" xyz="0 0 0"/> <mass value="1e-09"/> <inertia ixx="1e-09" ixy="0" ixz="0" iyy="1e-09" iyz="0" izz="1e-09"/> </inertial> <!-- Part part_1_5 --> <visual> <origin rpy="-1.5708 -1.5708 0" xyz="0 0 -0.0075"/> <geometry> <mesh filename="file:///home/alexander/simplebot2/ros2_workspace/install/simplebot_description/share/simplebot_description/meshes/part_1__3.stl"/> </geometry> <material name="part_1_5_material"> <color rgba="0.615686 0.811765 0.929412 1"/> </material> </visual> <collision> <origin rpy="-1.5708 -1.5708 0" xyz="0 0 -0.0075"/> <geometry> <mesh filename="file:///home/alexander/simplebot2/ros2_workspace/install/simplebot_description/share/simplebot_description/meshes/part_1__3.stl"/> </geometry> </collision> </link> <!-- Joint from base_link to part_1_3 --> <joint name="Revolute 3" type="continuous"> <origin rpy="-1.5708 -0 1.5708" xyz="-0.0629675 0.253869 -0.0793943"/> <parent link="base_link"/> <child link="part_1_3"/> <axis xyz="0 0 1"/> <limit effort="10" lower="-3.141592653589793" upper="3.141592653589793" velocity="10"/> </joint> <!-- Link part_1_4 --> <link name="part_1_4"> <inertial> <origin rpy="0 0 0" xyz="0 0 0"/> <mass value="1e-09"/> <inertia ixx="1e-09" ixy="0" ixz="0" iyy="1e-09" iyz="0" izz="1e-09"/> </inertial> <!-- Part part_1_6 --> <visual> <origin rpy="-1.5708 -1.5708 0" xyz="0 0 -0.0075"/> <geometry> <mesh filename="file:///home/alexander/simplebot2/ros2_workspace/install/simplebot_description/share/simplebot_description/meshes/part_1__3.stl"/> </geometry> <material name="part_1_6_material"> <color rgba="0.615686 0.811765 0.929412 1"/> </material> </visual> <collision> <origin rpy="-1.5708 -1.5708 0" xyz="0 0 -0.0075"/> <geometry> <mesh filename="file:///home/alexander/simplebot2/ros2_workspace/install/simplebot_description/share/simplebot_description/meshes/part_1__3.stl"/> </geometry> </collision> </link> <!-- Joint from base_link to part_1_4 --> <joint name="Revolute 4" type="continuous"> <origin rpy="-1.5708 -0 1.5708" xyz="-0.0629675 0.123869 -0.0793943"/> <parent link="base_link"/> <child link="part_1_4"/> <axis xyz="0 0 1"/> <limit effort="10" lower="-3.141592653589793" upper="3.141592653589793" velocity="10"/> </joint> </robot>
---
