<?xml version="1.0" ?>
<!-- Generated using onshape-to-robot -->
<!-- Onshape https://cad.onshape.com/documents/58d69eaf54d5097cb2ee2932/w/94ca09f7b1264f3339bd84c4/e/3159eab8c0fb4f293d9f6567 -->
<robot name="simplebot2">
  <!-- Link bottom_bracket -->
  <link name="bottom_bracket">
    <inertial>
      <origin xyz="0.0758413 0.0254907 -0.00612636" rpy="0 0 0"/>
      <mass value="0.426296"/>
      <inertia ixx="0.00184221" ixy="9.36048e-11" ixz="-1.22606e-12" iyy="0.00190478" iyz="2.8119e-08" izz="0.00332037"/>
    </inertial>
    <!-- Part frame3 -->
    <visual>
      <origin xyz="-0.0091587 0.0254907 -0.0322355" rpy="0 -0 -1.5708"/>
      <geometry>
        <mesh filename="package://assets/frame3.stl"/>
      </geometry>
      <material name="frame3_material">
        <color rgba="0.615686 0.811765 0.929412 1"/>
      </material>
    </visual>
    <collision>
      <origin xyz="-0.0091587 0.0254907 -0.0322355" rpy="0 -0 -1.5708"/>
      <geometry>
        <mesh filename="package://assets/frame3.stl"/>
      </geometry>
    </collision>
    <!-- Part side_bracket_right -->
    <visual>
      <origin xyz="-0.0091587 0.0254907 -0.0322355" rpy="0 -0 -1.5708"/>
      <geometry>
        <mesh filename="package://assets/side_bracket_right.stl"/>
      </geometry>
      <material name="side_bracket_right_material">
        <color rgba="0.647059 0.647059 0.647059 1"/>
      </material>
    </visual>
    <collision>
      <origin xyz="-0.0091587 0.0254907 -0.0322355" rpy="0 -0 -1.5708"/>
      <geometry>
        <mesh filename="package://assets/side_bracket_right.stl"/>
      </geometry>
    </collision>
    <!-- Part frame2 -->
    <visual>
      <origin xyz="-0.0091587 0.0254907 -0.0322355" rpy="0 -0 -1.5708"/>
      <geometry>
        <mesh filename="package://assets/frame2.stl"/>
      </geometry>
      <material name="frame2_material">
        <color rgba="0.615686 0.811765 0.929412 1"/>
      </material>
    </visual>
    <collision>
      <origin xyz="-0.0091587 0.0254907 -0.0322355" rpy="0 -0 -1.5708"/>
      <geometry>
        <mesh filename="package://assets/frame2.stl"/>
      </geometry>
    </collision>
    <!-- Part part_33 -->
    <visual>
      <origin xyz="-0.0091587 0.0254907 -0.0322355" rpy="0 -0 -1.5708"/>
      <geometry>
        <mesh filename="package://assets/part_33.stl"/>
      </geometry>
      <material name="part_33_material">
        <color rgba="0.980392 0.713725 0.00392157 1"/>
      </material>
    </visual>
    <collision>
      <origin xyz="-0.0091587 0.0254907 -0.0322355" rpy="0 -0 -1.5708"/>
      <geometry>
        <mesh filename="package://assets/part_33.stl"/>
      </geometry>
    </collision>
    <!-- Part motor_bracket_front_right -->
    <visual>
      <origin xyz="-0.0091587 0.0254907 -0.0322355" rpy="0 -0 -1.5708"/>
      <geometry>
        <mesh filename="package://assets/motor_bracket_front_right.stl"/>
      </geometry>
      <material name="motor_bracket_front_right_material">
        <color rgba="0.647059 0.647059 0.647059 1"/>
      </material>
    </visual>
    <collision>
      <origin xyz="-0.0091587 0.0254907 -0.0322355" rpy="0 -0 -1.5708"/>
      <geometry>
        <mesh filename="package://assets/motor_bracket_front_right.stl"/>
      </geometry>
    </collision>
    <!-- Part part_1 -->
    <visual>
      <origin xyz="-0.0091587 0.0254907 -0.0322355" rpy="0 -0 -1.5708"/>
      <geometry>
        <mesh filename="package://assets/part_1.stl"/>
      </geometry>
      <material name="part_1_material">
        <color rgba="0.647059 0.647059 0.647059 1"/>
      </material>
    </visual>
    <collision>
      <origin xyz="-0.0091587 0.0254907 -0.0322355" rpy="0 -0 -1.5708"/>
      <geometry>
        <mesh filename="package://assets/part_1.stl"/>
      </geometry>
    </collision>
    <!-- Part motor_bracket_front_left -->
    <visual>
      <origin xyz="-0.0091587 0.0254907 -0.0322355" rpy="0 -0 -1.5708"/>
      <geometry>
        <mesh filename="package://assets/motor_bracket_front_left.stl"/>
      </geometry>
      <material name="motor_bracket_front_left_material">
        <color rgba="0.647059 0.647059 0.647059 1"/>
      </material>
    </visual>
    <collision>
      <origin xyz="-0.0091587 0.0254907 -0.0322355" rpy="0 -0 -1.5708"/>
      <geometry>
        <mesh filename="package://assets/motor_bracket_front_left.stl"/>
      </geometry>
    </collision>
    <!-- Part frame4 -->
    <visual>
      <origin xyz="-0.0091587 0.0254907 -0.0322355" rpy="0 -0 -1.5708"/>
      <geometry>
        <mesh filename="package://assets/frame4.stl"/>
      </geometry>
      <material name="frame4_material">
        <color rgba="0.615686 0.811765 0.929412 1"/>
      </material>
    </visual>
    <collision>
      <origin xyz="-0.0091587 0.0254907 -0.0322355" rpy="0 -0 -1.5708"/>
      <geometry>
        <mesh filename="package://assets/frame4.stl"/>
      </geometry>
    </collision>
    <!-- Part motor_bracket_rear_left -->
    <visual>
      <origin xyz="-0.0091587 0.0254907 -0.0322355" rpy="0 -0 -1.5708"/>
      <geometry>
        <mesh filename="package://assets/motor_bracket_rear_left.stl"/>
      </geometry>
      <material name="motor_bracket_rear_left_material">
        <color rgba="0.647059 0.647059 0.647059 1"/>
      </material>
    </visual>
    <collision>
      <origin xyz="-0.0091587 0.0254907 -0.0322355" rpy="0 -0 -1.5708"/>
      <geometry>
        <mesh filename="package://assets/motor_bracket_rear_left.stl"/>
      </geometry>
    </collision>
    <!-- Part part_1_2 -->
    <visual>
      <origin xyz="-0.0091587 0.0254907 -0.0322355" rpy="-6.16298e-33 -0 -1.5708"/>
      <geometry>
        <mesh filename="package://assets/part_1__2.stl"/>
      </geometry>
      <material name="part_1_2_material">
        <color rgba="0.231373 0.380392 0.705882 1"/>
      </material>
    </visual>
    <collision>
      <origin xyz="-0.0091587 0.0254907 -0.0322355" rpy="-6.16298e-33 -0 -1.5708"/>
      <geometry>
        <mesh filename="package://assets/part_1__2.stl"/>
      </geometry>
    </collision>
    <!-- Part part_22 -->
    <visual>
      <origin xyz="-0.0091587 0.0254907 -0.0322355" rpy="0 -0 -1.5708"/>
      <geometry>
        <mesh filename="package://assets/part_22.stl"/>
      </geometry>
      <material name="part_22_material">
        <color rgba="0.917647 0.917647 0.917647 1"/>
      </material>
    </visual>
    <collision>
      <origin xyz="-0.0091587 0.0254907 -0.0322355" rpy="0 -0 -1.5708"/>
      <geometry>
        <mesh filename="package://assets/part_22.stl"/>
      </geometry>
    </collision>
    <!-- Part motor_bracket_rear_right -->
    <visual>
      <origin xyz="-0.0091587 0.0254907 -0.0322355" rpy="0 -0 -1.5708"/>
      <geometry>
        <mesh filename="package://assets/motor_bracket_rear_right.stl"/>
      </geometry>
      <material name="motor_bracket_rear_right_material">
        <color rgba="0.647059 0.647059 0.647059 1"/>
      </material>
    </visual>
    <collision>
      <origin xyz="-0.0091587 0.0254907 -0.0322355" rpy="0 -0 -1.5708"/>
      <geometry>
        <mesh filename="package://assets/motor_bracket_rear_right.stl"/>
      </geometry>
    </collision>
    <!-- Part frame1 -->
    <visual>
      <origin xyz="-0.0091587 0.0254907 -0.0322355" rpy="0 -0 -1.5708"/>
      <geometry>
        <mesh filename="package://assets/frame1.stl"/>
      </geometry>
      <material name="frame1_material">
        <color rgba="0.615686 0.811765 0.929412 1"/>
      </material>
    </visual>
    <collision>
      <origin xyz="-0.0091587 0.0254907 -0.0322355" rpy="0 -0 -1.5708"/>
      <geometry>
        <mesh filename="package://assets/frame1.stl"/>
      </geometry>
    </collision>
    <!-- Part side_bracket_left -->
    <visual>
      <origin xyz="-0.0091587 0.0254907 -0.0322355" rpy="0 -0 -1.5708"/>
      <geometry>
        <mesh filename="package://assets/side_bracket_left.stl"/>
      </geometry>
      <material name="side_bracket_left_material">
        <color rgba="0.647059 0.647059 0.647059 1"/>
      </material>
    </visual>
    <collision>
      <origin xyz="-0.0091587 0.0254907 -0.0322355" rpy="0 -0 -1.5708"/>
      <geometry>
        <mesh filename="package://assets/side_bracket_left.stl"/>
      </geometry>
    </collision>
    <!-- Part motor_front_right -->
    <visual>
      <origin xyz="0.123341 0.0254907 0.135265" rpy="-1.5708 -0 -1.5708"/>
      <geometry>
        <mesh filename="package://assets/motor_front_right.stl"/>
      </geometry>
      <material name="motor_front_right_material">
        <color rgba="0.8 0.807843 0.8 1"/>
      </material>
    </visual>
    <collision>
      <origin xyz="0.123341 0.0254907 0.135265" rpy="-1.5708 -0 -1.5708"/>
      <geometry>
        <mesh filename="package://assets/motor_front_right.stl"/>
      </geometry>
    </collision>
    <!-- Part motor_rear_left -->
    <visual>
      <origin xyz="-0.0066587 0.0254907 0.00526451" rpy="-1.5708 -0 -1.5708"/>
      <geometry>
        <mesh filename="package://assets/motor_rear_left.stl"/>
      </geometry>
      <material name="motor_rear_left_material">
        <color rgba="0.8 0.807843 0.8 1"/>
      </material>
    </visual>
    <collision>
      <origin xyz="-0.0066587 0.0254907 0.00526451" rpy="-1.5708 -0 -1.5708"/>
      <geometry>
        <mesh filename="package://assets/motor_rear_left.stl"/>
      </geometry>
    </collision>
    <!-- Part motor_rear_right -->
    <visual>
      <origin xyz="0.0283413 0.0254907 -0.0347355" rpy="1.5708 -0 -1.5708"/>
      <geometry>
        <mesh filename="package://assets/motor_rear_right.stl"/>
      </geometry>
      <material name="motor_rear_right_material">
        <color rgba="0.8 0.807843 0.8 1"/>
      </material>
    </visual>
    <collision>
      <origin xyz="0.0283413 0.0254907 -0.0347355" rpy="1.5708 -0 -1.5708"/>
      <geometry>
        <mesh filename="package://assets/motor_rear_right.stl"/>
      </geometry>
    </collision>
    <!-- Part bottom_bracket -->
    <visual>
      <origin xyz="-0.0091587 0.0254907 -0.0322355" rpy="0 -0 -1.5708"/>
      <geometry>
        <mesh filename="package://assets/bottom_bracket.stl"/>
      </geometry>
      <material name="bottom_bracket_material">
        <color rgba="0.917647 0.917647 0.917647 1"/>
      </material>
    </visual>
    <collision>
      <origin xyz="-0.0091587 0.0254907 -0.0322355" rpy="0 -0 -1.5708"/>
      <geometry>
        <mesh filename="package://assets/bottom_bracket.stl"/>
      </geometry>
    </collision>
    <!-- Part part_27 -->
    <visual>
      <origin xyz="-0.0091587 0.0254907 -0.0346755" rpy="0 -0 -1.5708"/>
      <geometry>
        <mesh filename="package://assets/part_27.stl"/>
      </geometry>
      <material name="part_27_material">
        <color rgba="0.980392 0.713725 0.00392157 1"/>
      </material>
    </visual>
    <collision>
      <origin xyz="-0.0091587 0.0254907 -0.0346755" rpy="0 -0 -1.5708"/>
      <geometry>
        <mesh filename="package://assets/part_27.stl"/>
      </geometry>
    </collision>
    <!-- Part motor_front_left -->
    <visual>
      <origin xyz="0.158341 0.0254907 -0.164735" rpy="1.5708 -0 -1.5708"/>
      <geometry>
        <mesh filename="package://assets/motor_front_left.stl"/>
      </geometry>
      <material name="motor_front_left_material">
        <color rgba="0.8 0.807843 0.8 1"/>
      </material>
    </visual>
    <collision>
      <origin xyz="0.158341 0.0254907 -0.164735" rpy="1.5708 -0 -1.5708"/>
      <geometry>
        <mesh filename="package://assets/motor_front_left.stl"/>
      </geometry>
    </collision>
  </link>
  <!-- Link part_1 -->
  <link name="part_1">
    <inertial>
      <origin xyz="0 0 0" rpy="0 0 0"/>
      <mass value="1e-09"/>
      <inertia ixx="1e-09" ixy="0" ixz="0" iyy="1e-09" iyz="0" izz="1e-09"/>
    </inertial>
    <!-- Part part_1_3 -->
    <visual>
      <origin xyz="1.73472e-18 0 0.0075" rpy="1.5708 1.5708 0"/>
      <geometry>
        <mesh filename="package://assets/part_1__3.stl"/>
      </geometry>
      <material name="part_1_3_material">
        <color rgba="0.615686 0.811765 0.929412 1"/>
      </material>
    </visual>
    <collision>
      <origin xyz="1.73472e-18 0 0.0075" rpy="1.5708 1.5708 0"/>
      <geometry>
        <mesh filename="package://assets/part_1__3.stl"/>
      </geometry>
    </collision>
  </link>
  <!-- Joint from bottom_bracket to part_1 -->
  <joint name="Revolute 1" type="revolute">
    <origin xyz="0.0108413 -0.0775176 -0.0147355" rpy="-1.5708 -0 -1.66533e-16"/>
    <parent link="bottom_bracket"/>
    <child link="part_1"/>
    <axis xyz="0 0 1"/>
    <limit effort="10" velocity="10" lower="-3.141592653589793" upper="3.141592653589793"/>
  </joint>
  <!-- Link part_1_2 -->
  <link name="part_1_2">
    <inertial>
      <origin xyz="0 0 0" rpy="0 0 0"/>
      <mass value="1e-09"/>
      <inertia ixx="1e-09" ixy="0" ixz="0" iyy="1e-09" iyz="0" izz="1e-09"/>
    </inertial>
    <!-- Part part_1_4 -->
    <visual>
      <origin xyz="0 0 0.0075" rpy="1.5708 1.5708 0"/>
      <geometry>
        <mesh filename="package://assets/part_1__3.stl"/>
      </geometry>
      <material name="part_1_4_material">
        <color rgba="0.615686 0.811765 0.929412 1"/>
      </material>
    </visual>
    <collision>
      <origin xyz="0 0 0.0075" rpy="1.5708 1.5708 0"/>
      <geometry>
        <mesh filename="package://assets/part_1__3.stl"/>
      </geometry>
    </collision>
  </link>
  <!-- Joint from bottom_bracket to part_1_2 -->
  <joint name="Revolute 2" type="revolute">
    <origin xyz="0.140841 -0.0775176 -0.0147355" rpy="-1.5708 -0 -1.66533e-16"/>
    <parent link="bottom_bracket"/>
    <child link="part_1_2"/>
    <axis xyz="0 0 1"/>
    <limit effort="10" velocity="10" lower="-3.141592653589793" upper="3.141592653589793"/>
  </joint>
  <!-- Link part_1_3 -->
  <link name="part_1_3">
    <inertial>
      <origin xyz="0 0 0" rpy="0 0 0"/>
      <mass value="1e-09"/>
      <inertia ixx="1e-09" ixy="0" ixz="0" iyy="1e-09" iyz="0" izz="1e-09"/>
    </inertial>
    <!-- Part part_1_5 -->
    <visual>
      <origin xyz="0 0 -0.0075" rpy="-1.5708 -1.5708 0"/>
      <geometry>
        <mesh filename="package://assets/part_1__3.stl"/>
      </geometry>
      <material name="part_1_5_material">
        <color rgba="0.615686 0.811765 0.929412 1"/>
      </material>
    </visual>
    <collision>
      <origin xyz="0 0 -0.0075" rpy="-1.5708 -1.5708 0"/>
      <geometry>
        <mesh filename="package://assets/part_1__3.stl"/>
      </geometry>
    </collision>
  </link>
  <!-- Joint from bottom_bracket to part_1_3 -->
  <joint name="Revolute 3" type="revolute">
    <origin xyz="0.140841 0.128499 -0.0147355" rpy="-1.5708 -0 -1.66533e-16"/>
    <parent link="bottom_bracket"/>
    <child link="part_1_3"/>
    <axis xyz="0 0 1"/>
    <limit effort="10" velocity="10" lower="-3.141592653589793" upper="3.141592653589793"/>
  </joint>
  <!-- Link part_1_4 -->
  <link name="part_1_4">
    <inertial>
      <origin xyz="0 0 0" rpy="0 0 0"/>
      <mass value="1e-09"/>
      <inertia ixx="1e-09" ixy="0" ixz="0" iyy="1e-09" iyz="0" izz="1e-09"/>
    </inertial>
    <!-- Part part_1_6 -->
    <visual>
      <origin xyz="-1.73472e-18 0 -0.0075" rpy="-1.5708 -1.5708 0"/>
      <geometry>
        <mesh filename="package://assets/part_1__3.stl"/>
      </geometry>
      <material name="part_1_6_material">
        <color rgba="0.615686 0.811765 0.929412 1"/>
      </material>
    </visual>
    <collision>
      <origin xyz="-1.73472e-18 0 -0.0075" rpy="-1.5708 -1.5708 0"/>
      <geometry>
        <mesh filename="package://assets/part_1__3.stl"/>
      </geometry>
    </collision>
  </link>
  <!-- Joint from bottom_bracket to part_1_4 -->
  <joint name="Revolute 4" type="revolute">
    <origin xyz="0.0108413 0.128499 -0.0147355" rpy="-1.5708 -0 -1.66533e-16"/>
    <parent link="bottom_bracket"/>
    <child link="part_1_4"/>
    <axis xyz="0 0 1"/>
    <limit effort="10" velocity="10" lower="-3.141592653589793" upper="3.141592653589793"/>
  </joint>
</robot>
