<?xml version="1.0"?>
<robot xmlns:xacro="http://www.ros.org/wiki/xacro">
  <xacro:include filename="$(find simplebot_description)/urdf/wheel.xacro"/>

  <xacro:macro name="drive_wheel" params="side position x y z">
    <xacro:wheel name="wheel_${position}_${side}" color="0.1 0.1 0.1 1"/>
    
    <joint name="${position}_${side}_wheel_joint" type="continuous">
      <parent link="base_link"/>
      <child link="wheel_${position}_${side}"/>
      <origin xyz="${x} ${y} ${z}" rpy="0 0 0"/>
      <axis xyz="0 1 0"/>
      <limit effort="5.0" velocity="20.0"/>
    </joint>
  </xacro:macro>
  
    <gazebo reference="lidar_link">
  <sensor name="lidar" type="gpu_lidar">
    <topic>scan</topic>
    <update_rate>10</update_rate>
    
    <gz_frame_id>lidar_link</gz_frame_id> 
    
    <lidar>
      <scan>
        <horizontal>
          <samples>720</samples>
          <resolution>1</resolution>
          <min_angle>-3.14159</min_angle>
          <max_angle>3.14159</max_angle>
        </horizontal>
      </scan>
      <range>
        <min>0.15</min>
        <max>12.0</max>
      </range>
    </lidar>
    <always_on>true</always_on>
    <visualize>true</visualize>
  </sensor>
</gazebo>
</robot>