<?xml version="1.0" ?>
<!-- Generated using onshape-to-robot -->
<!-- Onshape https://cad.onshape.com/documents/58d69eaf54d5097cb2ee2932/w/94ca09f7b1264f3339bd84c4/e/3159eab8c0fb4f293d9f6567 -->
<robot name="simplebot2" xmlns:xacro="http://www.ros.org/wiki/xacro">
  <xacro:include filename="$(find simplebot_description)/urdf/wheel.xacro"/>
  <!-- Link base_link -->
  <link name="base_footprint"/>

  <joint name="base_joint" type="fixed">
    <parent link="base_footprint"/>
    <child link="base_link"/>
    <origin xyz="0 0 0" rpy="0 0 0"/>
  </joint>

  <link name="base_link">
    <inertial>
      <origin xyz="-3.23026e-10 4.0693e-18 0.0211091" rpy="0 0 0"/>
      <mass value="0.426296"/>
      <inertia ixx="0.00184221" ixy="9.36048e-11" ixz="-1.22606e-12" iyy="0.00190478" iyz="2.8119e-08" izz="0.00332037"/>
    </inertial>
    <!-- Part frame3 -->
    <visual name="frame3">
      <origin xyz="-0.085 2.42861e-17 -0.005" rpy="0 -0 -1.5708"/>
      <geometry>
        <mesh filename="file://$(find simplebot_description)/meshes/simplebot/frame3.stl"/>
      </geometry>
      <material name="frame3_material">
        <color rgba="0.615686 0.811765 0.929412 1"/>
      </material>
    </visual>

    <!-- Part side_bracket_right -->
    <visual name="side_bracket_right">
      <origin xyz="-0.085 1.04083e-17 -0.005" rpy="0 -0 -1.5708"/>
      <geometry>
        <mesh filename="file://$(find simplebot_description)/meshes/simplebot/side_bracket_right.stl"/>
      </geometry>
      <material name="side_bracket_right_material">
        <color rgba="0.647059 0.647059 0.647059 1"/>
      </material>
    </visual>

    <!-- Part frame2 -->
    <visual name="frame2">
      <origin xyz="-0.085 1.38778e-17 -0.005" rpy="0 -0 -1.5708"/>
      <geometry>
        <mesh filename="file://$(find simplebot_description)/meshes/simplebot/frame2.stl"/>
      </geometry>
      <material name="frame2_material">
        <color rgba="0.615686 0.811765 0.929412 1"/>
      </material>
    </visual>
   
    <!-- Part part_33 -->
    <visual name="part_33">
      <origin xyz="-0.085 2.42861e-17 -0.005" rpy="0 -0 -1.5708"/>
      <geometry>
        <mesh filename="file://$(find simplebot_description)/meshes/simplebot/part_33.stl"/>
      </geometry>
      <material name="part_33_material">
        <color rgba="0.980392 0.713725 0.00392157 1"/>
      </material>
    </visual>

    <!-- Part motor_bracket_front_right -->
    <visual name="motor_bracket_front_right">
      <origin xyz="-0.085 2.77556e-17 -0.005" rpy="0 -0 -1.5708"/>
      <geometry>
        <mesh filename="file://$(find simplebot_description)/meshes/simplebot/motor_bracket_front_right.stl"/>
      </geometry>
      <material name="motor_bracket_front_right_material">
        <color rgba="0.647059 0.647059 0.647059 1"/>
      </material>
    </visual>

    <!-- Part motor_bracket_front_left -->
    <visual name="motor_bracket_front_left">
      <origin xyz="-0.085 2.77556e-17 -0.005" rpy="0 -0 -1.5708"/>
      <geometry>
        <mesh filename="file://$(find simplebot_description)/meshes/simplebot/motor_bracket_front_left.stl"/>
      </geometry>
      <material name="motor_bracket_front_left_material">
        <color rgba="0.647059 0.647059 0.647059 1"/>
      </material>
    </visual>

    <!-- Part frame4 -->
    <visual name="frame4">
      <origin xyz="-0.085 2.1684e-17 -0.005" rpy="0 -0 -1.5708"/>
      <geometry>
        <mesh filename="file://$(find simplebot_description)/meshes/simplebot/frame4.stl"/>
      </geometry>
      <material name="frame4_material">
        <color rgba="0.615686 0.811765 0.929412 1"/>
      </material>
    </visual>

    <!-- Part motor_bracket_rear_left -->
    <visual name="motor_bracket_rear_left">
      <origin xyz="-0.085 1.04083e-17 -0.005" rpy="0 -0 -1.5708"/>
      <geometry>
        <mesh filename="file://$(find simplebot_description)/meshes/simplebot/motor_bracket_rear_left.stl"/>
      </geometry>
      <material name="motor_bracket_rear_left_material">
        <color rgba="0.647059 0.647059 0.647059 1"/>
      </material>
    </visual>

    <!-- Part part_22 -->
    <visual name="part_22">
      <origin xyz="-0.085 2.42861e-17 -0.005" rpy="0 -0 -1.5708"/>
      <geometry>
        <mesh filename="file://$(find simplebot_description)/meshes/simplebot/part_22.stl"/>
      </geometry>
      <material name="part_22_material">
        <color rgba="0.917647 0.917647 0.917647 1"/>
      </material>
    </visual>

    <!-- Part motor_bracket_rear_right -->
    <visual name="motor_bracket_rear_right">
      <origin xyz="-0.085 1.04083e-17 -0.005" rpy="0 -0 -1.5708"/>
      <geometry>
        <mesh filename="file://$(find simplebot_description)/meshes/simplebot/motor_bracket_rear_right.stl"/>
      </geometry>
      <material name="motor_bracket_rear_right_material">
        <color rgba="0.647059 0.647059 0.647059 1"/>
      </material>
    </visual>

    <!-- Part frame1 -->
    <visual name="frame1">
      <origin xyz="-0.085 1.04083e-17 -0.005" rpy="0 -0 -1.5708"/>
      <geometry>
        <mesh filename="file://$(find simplebot_description)/meshes/simplebot/frame1.stl"/>
      </geometry>
      <material name="frame1_material">
        <color rgba="0.615686 0.811765 0.929412 1"/>
      </material>
    </visual>

    <!-- Part side_bracket_left -->
    <visual name="side_bracket_left">
      <origin xyz="-0.085 1.04083e-17 -0.005" rpy="0 -0 -1.5708"/>
      <geometry>
        <mesh filename="file://$(find simplebot_description)/meshes/simplebot/side_bracket_left.stl"/>
      </geometry>
      <material name="side_bracket_left_material">
        <color rgba="0.647059 0.647059 0.647059 1"/>
      </material>
    </visual>

    <!-- Part motor_front_right -->
    <visual name="motor_front_right">
      <origin xyz="0.0475 0 0.1625" rpy="-1.5708 -0 -1.5708"/>
      <geometry>
        <mesh filename="file://$(find simplebot_description)/meshes/simplebot/motor_front_right.stl"/>
      </geometry>
      <material name="motor_front_right_material">
        <color rgba="0.8 0.807843 0.8 1"/>
      </material>
    </visual>

    <!-- Part motor_rear_left -->
    <visual name="motor_rear_left">
      <origin xyz="-0.0825 1.38778e-17 0.0325" rpy="-1.5708 -0 -1.5708"/>
      <geometry>
        <mesh filename="file://$(find simplebot_description)/meshes/simplebot/motor_rear_left.stl"/>
      </geometry>
      <material name="motor_rear_left_material">
        <color rgba="0.8 0.807843 0.8 1"/>
      </material>
    </visual>

    <!-- Part motor_rear_right -->
    <visual name="motor_rear_right">
      <origin xyz="-0.0475 1.04083e-17 -0.0075" rpy="1.5708 -0 -1.5708"/>
      <geometry>
        <mesh filename="file://$(find simplebot_description)/meshes/simplebot/motor_rear_right.stl"/>
      </geometry>
      <material name="motor_rear_right_material">
        <color rgba="0.8 0.807843 0.8 1"/>
      </material>
    </visual>

    <!-- Part base_link -->
    <visual name="chassis_plate">
      <origin xyz="-0.085 -6.93889e-18 -0.005" rpy="0 -2.31296e-16 -1.5708"/>
      <geometry>
        <mesh filename="file://$(find simplebot_description)/meshes/simplebot/base_link.stl"/>
      </geometry>
      <material name="base_link_material">
        <color rgba="0.917647 0.917647 0.917647 1"/>
      </material>
    </visual>

    <!-- Part part_27 -->
    <visual name="part_27">
      <origin xyz="-0.085 1.04083e-17 -0.00744" rpy="0 -0 -1.5708"/>
      <geometry>
        <mesh filename="file://$(find simplebot_description)/meshes/simplebot/part_27.stl"/>
      </geometry>
      <material name="part_27_material">
        <color rgba="0.980392 0.713725 0.00392157 1"/>
      </material>
    </visual>

    <!-- Part motor_front_left -->
    <visual name="motor_front_left">
      <origin xyz="0.0825 -6.93889e-18 -0.1375" rpy="1.5708 -0 -1.5708"/>
      <geometry>
        <mesh filename="file://$(find simplebot_description)/meshes/simplebot/motor_front_left.stl"/>
      </geometry>
      <material name="motor_front_left_material">
        <color rgba="0.8 0.807843 0.8 1"/>
      </material>
    </visual>

  </link>

<xacro:wheel name="wheel_front_left" color="0.1 0.1 0.1 1"/>
  <joint name="joint_front_left" type="continuous">
    <parent link="base_link"/>
    <child link="wheel_front_left"/>
    <origin xyz="0.065 0.103008 0.010" rpy="0 0 0"/>
    <axis xyz="0 1 0"/>
    <limit effort="5.0" velocity="20.0"/>
  </joint>

  <xacro:wheel name="wheel_front_right" color="0.1 0.1 0.1 1"/>
  <joint name="joint_front_right" type="continuous">
    <parent link="base_link"/>
    <child link="wheel_front_right"/>
    <origin xyz="0.065 -0.103008 0.010" rpy="0 0 0"/>
    <axis xyz="0 1 0"/>
    <limit effort="5.0" velocity="20.0"/>
  </joint>

  <xacro:wheel name="wheel_rear_left" color="0.1 0.1 0.1 1"/>
  <joint name="joint_rear_left" type="continuous">
    <parent link="base_link"/>
    <child link="wheel_rear_left"/>
    <origin xyz="-0.065 0.103008 0.010" rpy="0 0 0"/>
    <axis xyz="0 1 0"/>
    <limit effort="5.0" velocity="20.0"/>
  </joint>

  <xacro:wheel name="wheel_rear_right" color="0.1 0.1 0.1 1"/>
  <joint name="joint_rear_right" type="continuous">
    <parent link="base_link"/>
    <child link="wheel_rear_right"/>
    <origin xyz="-0.065 -0.103008 0.010" rpy="0 0 0"/>
    <axis xyz="0 1 0"/>
    <limit effort="5.0" velocity="20.0"/>
  </joint>

  <gazebo>
    <plugin
    filename="gz-sim-diff-drive-system"
    name="gz::sim::systems::DiffDrive">
      <front_left_joint>joint_front_left</front_left_joint>
      <front_right_joint>joint_front_right</front_right_joint>
      <rear_left_joint>joint_rear_left</rear_left_joint>
      <rear_right_joint>joint_rear_right</rear_right_joint>

      <wheel_separation>0.206</wheel_separation>
      <wheelbase>0.13</wheelbase>
      <wheel_radius>0.03</wheel_radius>

      <topic>/cmd_vel</topic>
      <odom_topic>/odom</odom_topic>
      <frame_id>odom</frame_id>
      <child_frame_id>base_footprint</child_frame_id>

      <min_acceleration>-10</min_acceleration>
      <max_acceleration>10</max_acceleration>
      <min_velocity>-10</min_velocity>
      <max_velocity>10</max_velocity>
    </plugin>
  </gazebo>
</robot>